[2023-07-08 01:05:48,675] {taskinstance.py:1159} INFO - Dependencies all met for <TaskInstance: dados_climaticos.extrai_dados scheduled__2022-09-19T00:00:00+00:00 [queued]>
[2023-07-08 01:05:48,682] {taskinstance.py:1159} INFO - Dependencies all met for <TaskInstance: dados_climaticos.extrai_dados scheduled__2022-09-19T00:00:00+00:00 [queued]>
[2023-07-08 01:05:48,682] {taskinstance.py:1356} INFO - 
--------------------------------------------------------------------------------
[2023-07-08 01:05:48,682] {taskinstance.py:1357} INFO - Starting attempt 1 of 1
[2023-07-08 01:05:48,682] {taskinstance.py:1358} INFO - 
--------------------------------------------------------------------------------
[2023-07-08 01:05:48,720] {taskinstance.py:1377} INFO - Executing <Task(PythonOperator): extrai_dados> on 2022-09-19 00:00:00+00:00
[2023-07-08 01:05:48,724] {standard_task_runner.py:52} INFO - Started process 38168 to run task
[2023-07-08 01:05:48,727] {standard_task_runner.py:79} INFO - Running: ['airflow', 'tasks', 'run', 'dados_climaticos', 'extrai_dados', 'scheduled__2022-09-19T00:00:00+00:00', '--job-id', '35', '--raw', '--subdir', 'DAGS_FOLDER/dados_climaticos.py', '--cfg-path', '/tmp/tmpgiybrok1', '--error-file', '/tmp/tmp1fcx307g']
[2023-07-08 01:05:48,728] {standard_task_runner.py:80} INFO - Job 35: Subtask extrai_dados
[2023-07-08 01:05:48,771] {task_command.py:370} INFO - Running <TaskInstance: dados_climaticos.extrai_dados scheduled__2022-09-19T00:00:00+00:00 [running]> on host lucas-Estudos
[2023-07-08 01:05:48,882] {taskinstance.py:1569} INFO - Exporting the following env vars:
AIRFLOW_CTX_DAG_OWNER=airflow
AIRFLOW_CTX_DAG_ID=dados_climaticos
AIRFLOW_CTX_TASK_ID=extrai_dados
AIRFLOW_CTX_EXECUTION_DATE=2022-09-19T00:00:00+00:00
AIRFLOW_CTX_TRY_NUMBER=1
AIRFLOW_CTX_DAG_RUN_ID=scheduled__2022-09-19T00:00:00+00:00
[2023-07-08 01:05:49,538] {process_utils.py:125} INFO - Sending Signals.SIGTERM to group 38168. PIDs of all processes in the group: [38168]
[2023-07-08 01:05:49,540] {process_utils.py:80} INFO - Sending the signal Signals.SIGTERM to group 38168
[2023-07-08 01:05:49,546] {taskinstance.py:1541} ERROR - Received SIGTERM. Terminating subprocesses.
[2023-07-08 01:05:49,564] {taskinstance.py:1889} ERROR - Task failed with exception
Traceback (most recent call last):
  File "/home/lucas/Área de Trabalho/apresentação/venv/lib/python3.10/site-packages/airflow/operators/python.py", line 171, in execute
    return_value = self.execute_callable()
  File "/home/lucas/Área de Trabalho/apresentação/venv/lib/python3.10/site-packages/airflow/operators/python.py", line 189, in execute_callable
    return self.python_callable(*self.op_args, **self.op_kwargs)
  File "/home/lucas/Área de Trabalho/apresentação/airflow/dags/dados_climaticos.py", line 27, in extrai_dados
    dados = pd.read_csv(URL)
  File "/home/lucas/Área de Trabalho/apresentação/venv/lib/python3.10/site-packages/pandas/io/parsers/readers.py", line 912, in read_csv
    return _read(filepath_or_buffer, kwds)
  File "/home/lucas/Área de Trabalho/apresentação/venv/lib/python3.10/site-packages/pandas/io/parsers/readers.py", line 577, in _read
    parser = TextFileReader(filepath_or_buffer, **kwds)
  File "/home/lucas/Área de Trabalho/apresentação/venv/lib/python3.10/site-packages/pandas/io/parsers/readers.py", line 1407, in __init__
    self._engine = self._make_engine(f, self.engine)
  File "/home/lucas/Área de Trabalho/apresentação/venv/lib/python3.10/site-packages/pandas/io/parsers/readers.py", line 1661, in _make_engine
    self.handles = get_handle(
  File "/home/lucas/Área de Trabalho/apresentação/venv/lib/python3.10/site-packages/pandas/io/common.py", line 716, in get_handle
    ioargs = _get_filepath_or_buffer(
  File "/home/lucas/Área de Trabalho/apresentação/venv/lib/python3.10/site-packages/pandas/io/common.py", line 368, in _get_filepath_or_buffer
    with urlopen(req_info) as req:
  File "/home/lucas/Área de Trabalho/apresentação/venv/lib/python3.10/site-packages/pandas/io/common.py", line 270, in urlopen
    return urllib.request.urlopen(*args, **kwargs)
  File "/usr/lib/python3.10/urllib/request.py", line 216, in urlopen
    return opener.open(url, data, timeout)
  File "/usr/lib/python3.10/urllib/request.py", line 519, in open
    response = self._open(req, data)
  File "/usr/lib/python3.10/urllib/request.py", line 536, in _open
    result = self._call_chain(self.handle_open, protocol, protocol +
  File "/usr/lib/python3.10/urllib/request.py", line 496, in _call_chain
    result = func(*args)
  File "/usr/lib/python3.10/urllib/request.py", line 1391, in https_open
    return self.do_open(http.client.HTTPSConnection, req,
  File "/usr/lib/python3.10/urllib/request.py", line 1352, in do_open
    r = h.getresponse()
  File "/usr/lib/python3.10/http/client.py", line 1374, in getresponse
    response.begin()
  File "/usr/lib/python3.10/http/client.py", line 318, in begin
    version, status, reason = self._read_status()
  File "/usr/lib/python3.10/http/client.py", line 279, in _read_status
    line = str(self.fp.readline(_MAXLINE + 1), "iso-8859-1")
  File "/usr/lib/python3.10/socket.py", line 705, in readinto
    return self._sock.recv_into(b)
  File "/usr/lib/python3.10/ssl.py", line 1274, in recv_into
    return self.read(nbytes, buffer)
  File "/usr/lib/python3.10/ssl.py", line 1130, in read
    return self._sslobj.read(len, buffer)
  File "/home/lucas/Área de Trabalho/apresentação/venv/lib/python3.10/site-packages/airflow/models/taskinstance.py", line 1543, in signal_handler
    raise AirflowException("Task received SIGTERM signal")
airflow.exceptions.AirflowException: Task received SIGTERM signal
[2023-07-08 01:05:49,580] {taskinstance.py:1395} INFO - Marking task as FAILED. dag_id=dados_climaticos, task_id=extrai_dados, execution_date=20220919T000000, start_date=20230708T040548, end_date=20230708T040549
[2023-07-08 01:05:49,602] {standard_task_runner.py:92} ERROR - Failed to execute job 35 for task extrai_dados (Task received SIGTERM signal; 38168)
[2023-07-08 01:05:49,640] {process_utils.py:75} INFO - Process psutil.Process(pid=38168, status='terminated', exitcode=1, started='01:05:47') (38168) terminated with exit code 1
